<?xml version="1.0" ?>
<robot name="rb1" xmlns:xacro="http://www.ros.org/wiki/xacro">
    <xacro:include filename="$(find my_rb1_description)/urdf/my_rb1_description.gazebo" />

    <material name="blue">
        <color rgba="0 0 1 1"/>
    </material>

    <link name="base_footprint" />

    <joint name="base_footprint_base_joint" type="fixed">
        <parent link="base_footprint" />
        <child link="base_link" />
        <origin xyz="0 0 0.175" rpy="0 0 0" />
    </joint>

    <link name="base_link">
        <inertial>
            <mass value="20" />
            <inertia ixx="0.4625"  ixy="0"  ixz="0" iyy="0.4625" iyz="0" izz="0.625" />
        </inertial>
        <collision>
             <geometry>
                <cylinder radius="0.25" length="0.30" />
            </geometry>       
        </collision>
        <visual>
            <geometry>
                <cylinder radius="0.25" length="0.30" />
            </geometry>
            <material name="blue" />
        </visual>
    </link>

    <!-- Front Laser -->
    <joint name="front_laser_base_joint" type="fixed">
        <parent link="base_link" />
        <child link="front_laser" />
        <origin xyz="0.25 0 0.075" rpy="0 0 0" />
    </joint>    

    <link name="front_laser">
        <inertial>
            <mass value="0.5" />
            <inertia ixx="0.000115625"  ixy="0"  ixz="0" iyy="0.000115625" iyz="0" izz="0.00015625" />
        </inertial>
        <collision>
            <origin xyz="0 0 0" rpy="3.14 0 0" />
            <geometry>
                 <cylinder radius="0.025" length="0.03" />
            </geometry>
        </collision>
        <visual>
            <origin xyz="0 0 0" rpy="3.14 0 0" />
            <geometry>
                 <cylinder radius="0.025" length="0.03" />
            </geometry>
        </visual>
    </link>

    <!-- Left Wheel -->
    <joint name="left_wheel_base_joint" type="continuous">
        <parent link="base_link" />
        <child link="left_wheel" />
        <origin xyz="0 -0.2 -0.15" rpy="0 0 0" />
        <axis xyz="0 1 0" />
    </joint>

    <link name="left_wheel">
        <inertial>
            <mass value="2" />
            <inertia ixx="0.0153125"  ixy="0"  ixz="0" iyy="0.0153125" iyz="0" izz="0.000625" />
        </inertial>
        <collision>
            <origin xyz="0 0 0" rpy="1.57 0 0" />
            <geometry>
                <cylinder radius="0.025" length="0.03" />
            </geometry>
        </collision>
        <visual>
            <origin xyz="0 0 0" rpy="1.57 0 0" />
            <geometry>
                <cylinder radius="0.025" length="0.03" />
            </geometry>
        </visual>
    </link>

    <!-- Right Wheel -->
    <joint name="right_wheel_base_joint" type="continuous">
        <parent link="base_link" />
        <child link="right_wheel" />
        <origin xyz="0 0.2 -0.15" rpy="0 0 0" />
        <axis xyz="0 1 0" />
    </joint>

    <link name="right_wheel">
        <inertial>
            <mass value="2" />
           <inertia ixx="0.0153125"  ixy="0"  ixz="0" iyy="0.0153125" iyz="0" izz="0.000625" />
        </inertial>
        <collision>
            <origin xyz="0 0 0" rpy="-1.57 0 0" />
            <geometry>
                <cylinder radius="0.025" length="0.03" />
            </geometry>
        </collision>
        <visual>
            <origin xyz="0 0 0" rpy="-1.57 0 0" />
            <geometry>
                <cylinder radius="0.025" length="0.03" />
            </geometry>
        </visual>
    </link>

    <!-- Front Caster -->
    <joint name="front_caster_base_joint" type="fixed">
        <parent link="base_link" />
        <child link="front_caster" />
        <origin xyz="0.175 0.0 -0.15" rpy="0 0 0" />
    </joint>

    <link name="front_caster">
        <inertial>
            <mass value="0.25" />
            <inertia ixx="0.0000625" ixy="0" ixz="0" iyy="0.0000625" iyz="0" izz="0.0000625"/>
        </inertial>
        <collision>
            <geometry>
                <sphere radius="0.025" />
            </geometry>
        </collision>
        <visual>
            <geometry>
                <sphere radius="0.025" />
            </geometry>
        </visual>
    </link>

    <!-- Back Caster -->
    <joint name="back_caster_base_joint" type="fixed">
        <parent link="base_link" />
        <child link="back_caster" />
        <origin xyz="-0.175 0.0 -0.15" rpy="0 0 0" />
    </joint>

    <link name="back_caster">
        <inertial>
            <mass value="0.25" />
            <inertia ixx="0.0000625" ixy="0" ixz="0" iyy="0.0000625" iyz="0" izz="0.0000625"/>
        </inertial>
        <collision>
            <geometry>
                <sphere radius="0.025" />
            </geometry>
        </collision>
        <visual>
            <geometry>
                <sphere radius="0.025" />
            </geometry>
        </visual>
    </link>
</robot>